ERROR 2018-01-23 13:03:16,667 exception 4037 140075048556288 Internal Server Error: /about_me/
Traceback (most recent call last):
  File "/home/leonis/test/py3.5.2env/lib/python3.5/site-packages/django/core/handlers/exception.py", line 42, in inner
    response = get_response(request)
  File "/home/leonis/test/py3.5.2env/lib/python3.5/site-packages/django/core/handlers/base.py", line 187, in _get_response
    response = self.process_exception_by_middleware(e, request)
  File "/home/leonis/test/py3.5.2env/lib/python3.5/site-packages/django/core/handlers/base.py", line 185, in _get_response
    response = wrapped_callback(request, *callback_args, **callback_kwargs)
  File "/home/leonis/桌面/blogproject/blog/views.py", line 368, in about
    return render(request, 'blog/aboutme.html')
  File "/home/leonis/test/py3.5.2env/lib/python3.5/site-packages/django/shortcuts.py", line 30, in render
    content = loader.render_to_string(template_name, context, request, using=using)
  File "/home/leonis/test/py3.5.2env/lib/python3.5/site-packages/django/template/loader.py", line 67, in render_to_string
    template = get_template(template_name, using=using)
  File "/home/leonis/test/py3.5.2env/lib/python3.5/site-packages/django/template/loader.py", line 25, in get_template
    raise TemplateDoesNotExist(template_name, chain=chain)
django.template.exceptions.TemplateDoesNotExist: blog/aboutme.html
ERROR 2018-01-23 13:03:57,552 exception 4094 140484913047296 Internal Server Error: /about_me/
Traceback (most recent call last):
  File "/home/leonis/test/py3.5.2env/lib/python3.5/site-packages/django/core/handlers/exception.py", line 42, in inner
    response = get_response(request)
  File "/home/leonis/test/py3.5.2env/lib/python3.5/site-packages/django/core/handlers/base.py", line 187, in _get_response
    response = self.process_exception_by_middleware(e, request)
  File "/home/leonis/test/py3.5.2env/lib/python3.5/site-packages/django/core/handlers/base.py", line 185, in _get_response
    response = wrapped_callback(request, *callback_args, **callback_kwargs)
  File "/home/leonis/桌面/blogproject/blog/views.py", line 368, in about
    return render(request, 'blog/about_me.html')
  File "/home/leonis/test/py3.5.2env/lib/python3.5/site-packages/django/shortcuts.py", line 30, in render
    content = loader.render_to_string(template_name, context, request, using=using)
  File "/home/leonis/test/py3.5.2env/lib/python3.5/site-packages/django/template/loader.py", line 67, in render_to_string
    template = get_template(template_name, using=using)
  File "/home/leonis/test/py3.5.2env/lib/python3.5/site-packages/django/template/loader.py", line 25, in get_template
    raise TemplateDoesNotExist(template_name, chain=chain)
django.template.exceptions.TemplateDoesNotExist: blog/about_me.html
ERROR 2018-01-23 13:05:21,743 exception 4094 140484921702144 Internal Server Error: /about_me/
Traceback (most recent call last):
  File "/home/leonis/test/py3.5.2env/lib/python3.5/site-packages/django/urls/base.py", line 77, in reverse
    extra, resolver = resolver.namespace_dict[ns]
KeyError: 'blogproject'

During handling of the above exception, another exception occurred:

Traceback (most recent call last):
  File "/home/leonis/test/py3.5.2env/lib/python3.5/site-packages/django/core/handlers/exception.py", line 42, in inner
    response = get_response(request)
  File "/home/leonis/test/py3.5.2env/lib/python3.5/site-packages/django/core/handlers/base.py", line 187, in _get_response
    response = self.process_exception_by_middleware(e, request)
  File "/home/leonis/test/py3.5.2env/lib/python3.5/site-packages/django/core/handlers/base.py", line 185, in _get_response
    response = wrapped_callback(request, *callback_args, **callback_kwargs)
  File "/home/leonis/桌面/blogproject/blog/views.py", line 368, in about
    return render(request, 'blog/about_me.html')
  File "/home/leonis/test/py3.5.2env/lib/python3.5/site-packages/django/shortcuts.py", line 30, in render
    content = loader.render_to_string(template_name, context, request, using=using)
  File "/home/leonis/test/py3.5.2env/lib/python3.5/site-packages/django/template/loader.py", line 68, in render_to_string
    return template.render(context, request)
  File "/home/leonis/test/py3.5.2env/lib/python3.5/site-packages/django/template/backends/django.py", line 66, in render
    return self.template.render(context)
  File "/home/leonis/test/py3.5.2env/lib/python3.5/site-packages/django/template/base.py", line 208, in render
    return self._render(context)
  File "/home/leonis/test/py3.5.2env/lib/python3.5/site-packages/django/template/base.py", line 199, in _render
    return self.nodelist.render(context)
  File "/home/leonis/test/py3.5.2env/lib/python3.5/site-packages/django/template/base.py", line 994, in render
    bit = node.render_annotated(context)
  File "/home/leonis/test/py3.5.2env/lib/python3.5/site-packages/django/template/base.py", line 961, in render_annotated
    return self.render(context)
  File "/home/leonis/test/py3.5.2env/lib/python3.5/site-packages/django/template/defaulttags.py", line 439, in render
    url = reverse(view_name, args=args, kwargs=kwargs, current_app=current_app)
  File "/home/leonis/test/py3.5.2env/lib/python3.5/site-packages/django/urls/base.py", line 87, in reverse
    raise NoReverseMatch("%s is not a registered namespace" % key)
django.urls.exceptions.NoReverseMatch: 'blogproject' is not a registered namespace
ERROR 2018-01-23 13:05:42,160 exception 4206 139741562062592 Internal Server Error: /about_me/
Traceback (most recent call last):
  File "/home/leonis/test/py3.5.2env/lib/python3.5/site-packages/django/urls/base.py", line 77, in reverse
    extra, resolver = resolver.namespace_dict[ns]
KeyError: 'blogproject'

During handling of the above exception, another exception occurred:

Traceback (most recent call last):
  File "/home/leonis/test/py3.5.2env/lib/python3.5/site-packages/django/core/handlers/exception.py", line 42, in inner
    response = get_response(request)
  File "/home/leonis/test/py3.5.2env/lib/python3.5/site-packages/django/core/handlers/base.py", line 187, in _get_response
    response = self.process_exception_by_middleware(e, request)
  File "/home/leonis/test/py3.5.2env/lib/python3.5/site-packages/django/core/handlers/base.py", line 185, in _get_response
    response = wrapped_callback(request, *callback_args, **callback_kwargs)
  File "/home/leonis/桌面/blogproject/blog/views.py", line 368, in about
    return render(request, 'blog/about_me.html')
  File "/home/leonis/test/py3.5.2env/lib/python3.5/site-packages/django/shortcuts.py", line 30, in render
    content = loader.render_to_string(template_name, context, request, using=using)
  File "/home/leonis/test/py3.5.2env/lib/python3.5/site-packages/django/template/loader.py", line 68, in render_to_string
    return template.render(context, request)
  File "/home/leonis/test/py3.5.2env/lib/python3.5/site-packages/django/template/backends/django.py", line 66, in render
    return self.template.render(context)
  File "/home/leonis/test/py3.5.2env/lib/python3.5/site-packages/django/template/base.py", line 208, in render
    return self._render(context)
  File "/home/leonis/test/py3.5.2env/lib/python3.5/site-packages/django/template/base.py", line 199, in _render
    return self.nodelist.render(context)
  File "/home/leonis/test/py3.5.2env/lib/python3.5/site-packages/django/template/base.py", line 994, in render
    bit = node.render_annotated(context)
  File "/home/leonis/test/py3.5.2env/lib/python3.5/site-packages/django/template/base.py", line 961, in render_annotated
    return self.render(context)
  File "/home/leonis/test/py3.5.2env/lib/python3.5/site-packages/django/template/defaulttags.py", line 439, in render
    url = reverse(view_name, args=args, kwargs=kwargs, current_app=current_app)
  File "/home/leonis/test/py3.5.2env/lib/python3.5/site-packages/django/urls/base.py", line 87, in reverse
    raise NoReverseMatch("%s is not a registered namespace" % key)
django.urls.exceptions.NoReverseMatch: 'blogproject' is not a registered namespace
ERROR 2018-01-23 13:06:32,013 exception 4258 140153406539520 Internal Server Error: /about_me/
Traceback (most recent call last):
  File "/home/leonis/test/py3.5.2env/lib/python3.5/site-packages/django/urls/base.py", line 77, in reverse
    extra, resolver = resolver.namespace_dict[ns]
KeyError: 'blogproject'

During handling of the above exception, another exception occurred:

Traceback (most recent call last):
  File "/home/leonis/test/py3.5.2env/lib/python3.5/site-packages/django/core/handlers/exception.py", line 42, in inner
    response = get_response(request)
  File "/home/leonis/test/py3.5.2env/lib/python3.5/site-packages/django/core/handlers/base.py", line 187, in _get_response
    response = self.process_exception_by_middleware(e, request)
  File "/home/leonis/test/py3.5.2env/lib/python3.5/site-packages/django/core/handlers/base.py", line 185, in _get_response
    response = wrapped_callback(request, *callback_args, **callback_kwargs)
  File "/home/leonis/桌面/blogproject/blog/views.py", line 368, in about
    return render(request, 'blog/about_me.html')
  File "/home/leonis/test/py3.5.2env/lib/python3.5/site-packages/django/shortcuts.py", line 30, in render
    content = loader.render_to_string(template_name, context, request, using=using)
  File "/home/leonis/test/py3.5.2env/lib/python3.5/site-packages/django/template/loader.py", line 68, in render_to_string
    return template.render(context, request)
  File "/home/leonis/test/py3.5.2env/lib/python3.5/site-packages/django/template/backends/django.py", line 66, in render
    return self.template.render(context)
  File "/home/leonis/test/py3.5.2env/lib/python3.5/site-packages/django/template/base.py", line 208, in render
    return self._render(context)
  File "/home/leonis/test/py3.5.2env/lib/python3.5/site-packages/django/template/base.py", line 199, in _render
    return self.nodelist.render(context)
  File "/home/leonis/test/py3.5.2env/lib/python3.5/site-packages/django/template/base.py", line 994, in render
    bit = node.render_annotated(context)
  File "/home/leonis/test/py3.5.2env/lib/python3.5/site-packages/django/template/base.py", line 961, in render_annotated
    return self.render(context)
  File "/home/leonis/test/py3.5.2env/lib/python3.5/site-packages/django/template/defaulttags.py", line 439, in render
    url = reverse(view_name, args=args, kwargs=kwargs, current_app=current_app)
  File "/home/leonis/test/py3.5.2env/lib/python3.5/site-packages/django/urls/base.py", line 87, in reverse
    raise NoReverseMatch("%s is not a registered namespace" % key)
django.urls.exceptions.NoReverseMatch: 'blogproject' is not a registered namespace
ERROR 2018-01-23 13:33:27,116 exception 7483 140322605029120 Internal Server Error: /
Traceback (most recent call last):
  File "/home/leonis/test/py3.5.2env/lib/python3.5/site-packages/django/core/handlers/exception.py", line 42, in inner
    response = get_response(request)
  File "/home/leonis/test/py3.5.2env/lib/python3.5/site-packages/django/core/handlers/base.py", line 217, in _get_response
    response = self.process_exception_by_middleware(e, request)
  File "/home/leonis/test/py3.5.2env/lib/python3.5/site-packages/django/core/handlers/base.py", line 215, in _get_response
    response = response.render()
  File "/home/leonis/test/py3.5.2env/lib/python3.5/site-packages/django/template/response.py", line 109, in render
    self.content = self.rendered_content
  File "/home/leonis/test/py3.5.2env/lib/python3.5/site-packages/django/template/response.py", line 86, in rendered_content
    content = template.render(context, self._request)
  File "/home/leonis/test/py3.5.2env/lib/python3.5/site-packages/django/template/backends/django.py", line 66, in render
    return self.template.render(context)
  File "/home/leonis/test/py3.5.2env/lib/python3.5/site-packages/django/template/base.py", line 208, in render
    return self._render(context)
  File "/home/leonis/test/py3.5.2env/lib/python3.5/site-packages/django/template/base.py", line 199, in _render
    return self.nodelist.render(context)
  File "/home/leonis/test/py3.5.2env/lib/python3.5/site-packages/django/template/base.py", line 994, in render
    bit = node.render_annotated(context)
  File "/home/leonis/test/py3.5.2env/lib/python3.5/site-packages/django/template/base.py", line 961, in render_annotated
    return self.render(context)
  File "/home/leonis/test/py3.5.2env/lib/python3.5/site-packages/django/template/loader_tags.py", line 174, in render
    return compiled_parent._render(context)
  File "/home/leonis/test/py3.5.2env/lib/python3.5/site-packages/django/template/base.py", line 199, in _render
    return self.nodelist.render(context)
  File "/home/leonis/test/py3.5.2env/lib/python3.5/site-packages/django/template/base.py", line 994, in render
    bit = node.render_annotated(context)
  File "/home/leonis/test/py3.5.2env/lib/python3.5/site-packages/django/template/base.py", line 961, in render_annotated
    return self.render(context)
  File "/home/leonis/test/py3.5.2env/lib/python3.5/site-packages/django/template/defaulttags.py", line 439, in render
    url = reverse(view_name, args=args, kwargs=kwargs, current_app=current_app)
  File "/home/leonis/test/py3.5.2env/lib/python3.5/site-packages/django/urls/base.py", line 91, in reverse
    return force_text(iri_to_uri(resolver._reverse_with_prefix(view, prefix, *args, **kwargs)))
  File "/home/leonis/test/py3.5.2env/lib/python3.5/site-packages/django/urls/resolvers.py", line 392, in _reverse_with_prefix
    (lookup_view_s, args, kwargs, len(patterns), patterns)
django.urls.exceptions.NoReverseMatch: Reverse for 'contact' with arguments '()' and keyword arguments '{}' not found. 0 pattern(s) tried: []
ERROR 2018-01-23 13:34:09,803 exception 7534 139783166150400 Internal Server Error: /
Traceback (most recent call last):
  File "/home/leonis/test/py3.5.2env/lib/python3.5/site-packages/django/core/handlers/exception.py", line 42, in inner
    response = get_response(request)
  File "/home/leonis/test/py3.5.2env/lib/python3.5/site-packages/django/core/handlers/base.py", line 217, in _get_response
    response = self.process_exception_by_middleware(e, request)
  File "/home/leonis/test/py3.5.2env/lib/python3.5/site-packages/django/core/handlers/base.py", line 215, in _get_response
    response = response.render()
  File "/home/leonis/test/py3.5.2env/lib/python3.5/site-packages/django/template/response.py", line 109, in render
    self.content = self.rendered_content
  File "/home/leonis/test/py3.5.2env/lib/python3.5/site-packages/django/template/response.py", line 86, in rendered_content
    content = template.render(context, self._request)
  File "/home/leonis/test/py3.5.2env/lib/python3.5/site-packages/django/template/backends/django.py", line 66, in render
    return self.template.render(context)
  File "/home/leonis/test/py3.5.2env/lib/python3.5/site-packages/django/template/base.py", line 208, in render
    return self._render(context)
  File "/home/leonis/test/py3.5.2env/lib/python3.5/site-packages/django/template/base.py", line 199, in _render
    return self.nodelist.render(context)
  File "/home/leonis/test/py3.5.2env/lib/python3.5/site-packages/django/template/base.py", line 994, in render
    bit = node.render_annotated(context)
  File "/home/leonis/test/py3.5.2env/lib/python3.5/site-packages/django/template/base.py", line 961, in render_annotated
    return self.render(context)
  File "/home/leonis/test/py3.5.2env/lib/python3.5/site-packages/django/template/loader_tags.py", line 174, in render
    return compiled_parent._render(context)
  File "/home/leonis/test/py3.5.2env/lib/python3.5/site-packages/django/template/base.py", line 199, in _render
    return self.nodelist.render(context)
  File "/home/leonis/test/py3.5.2env/lib/python3.5/site-packages/django/template/base.py", line 994, in render
    bit = node.render_annotated(context)
  File "/home/leonis/test/py3.5.2env/lib/python3.5/site-packages/django/template/base.py", line 961, in render_annotated
    return self.render(context)
  File "/home/leonis/test/py3.5.2env/lib/python3.5/site-packages/django/template/defaulttags.py", line 439, in render
    url = reverse(view_name, args=args, kwargs=kwargs, current_app=current_app)
  File "/home/leonis/test/py3.5.2env/lib/python3.5/site-packages/django/urls/base.py", line 91, in reverse
    return force_text(iri_to_uri(resolver._reverse_with_prefix(view, prefix, *args, **kwargs)))
  File "/home/leonis/test/py3.5.2env/lib/python3.5/site-packages/django/urls/resolvers.py", line 392, in _reverse_with_prefix
    (lookup_view_s, args, kwargs, len(patterns), patterns)
django.urls.exceptions.NoReverseMatch: Reverse for 'contact' with arguments '()' and keyword arguments '{}' not found. 0 pattern(s) tried: []
